<?xml version="1.0"?>
<robot name="knob_exp">
    <link name="base_link">
        <visual >
            <origin rpy="0 0 0" xyz="-0.05 0 0" />
            <geometry >
                <box size="0.1 1 1" />
            </geometry>
            <material >
                <color rgba="0.8039 0.6667 0.4902 1" />
            </material>
        </visual>
        <collision >
            <origin rpy="0 0 0" xyz="-0.05 0 0" />
            <geometry >
                <box size="0.1 1 1" />
            </geometry>
        </collision>
        <inertial >
            <origin rpy="0 0 0" xyz="0 0 0" />
            <mass value="2.5" />
            <inertia izz="1.0" ixy="0.0" ixz="0.0" iyy="1.0" ixx="1.0" iyz="0.0" />
        </inertial>
    </link>
    <link name="knob_base">
        <visual >
            <origin rpy="0 0 0" xyz="0.01 0 0" />
            <geometry >
                <box size="0.02 0.15 0.15" />
            </geometry>
            <material >
                <color rgba="0.7 0.7 0.7 1" />
            </material>
        </visual>
        <collision >
            <origin rpy="0 0 0" xyz="0.01 0 0" />
            <geometry >
                <box size="0.02 0.15 0.15" />
            </geometry>
            <material >
                <color rgba="1 1 1 1" />
            </material>
        </collision>
        <inertial >
            <origin rpy="0 0 0" xyz="0 0 0" />
            <mass value="0.2" />
            <inertia izz="0.000833" ixy="0" ixz="0" iyy="0.000833" ixx="0.000833" iyz="0" />
        </inertial>
    </link>
    <link name="knob">
        <visual >
            <origin rpy="0 1.5707963267948966 0" xyz="0.04 0 0" />
            <geometry >
                <cylinder radius="0.02" length="0.05" />
            </geometry>
            <material >
                <color rgba="0.2 0.2 0.2 1" />
            </material>
        </visual>
        <inertial >
            <origin rpy="0 0 0" xyz="0 0 0" />
            <mass value="0.4" />
            <inertia izz="0.0001" ixy="0" ixz="0" iyy="0.0001" ixx="0.0001" iyz="0" />
        </inertial>
        <collision >
            <origin rpy="0 1.5707963267948966 0" xyz="0.04 0 0" />
            <geometry >
                <cylinder radius="0.02" length="0.05" />
            </geometry>
            <material >
                <color rgba="1 1 1 1" />
            </material>
        </collision>
    </link>
    <joint type="fixed" name="base_link_knob_base_joint">
        <parent link="base_link" />
        <child link="knob_base" />
        <origin rpy="0 0 0" xyz="0 0 0" />
    </joint>
    <joint type="revolute" name="actuator_1_joint">
        <parent link="knob_base" />
        <child link="knob" />
        <origin rpy="0 0 0" xyz="0 0 0" />
        <axis xyz="1 0 0" />
        <limit lower="-1.5707963267948966" upper="3.141592653589793" velocity="5" effort="2" />
        <dynamics friction="0.02" damping="0" />
    </joint>
    <link name="indicator">
        <visual >
            <origin rpy="0 1.5707963267948966 0" xyz="0.065 0 0.01" />
            <geometry >
                <box size="0.015 0.004 0.003" />
            </geometry>
            <material >
                <color rgba="1 0 0 1" />
            </material>
        </visual>
    </link>
    <joint type="fixed" name="knob_knob_indicator_joint">
        <parent link="knob" />
        <child link="indicator" />
        <origin rpy="0 0 0" xyz="0 0 0" />
    </joint>
</robot>
