<?xml version="1.0"?>
<robot name="knob_exp">
    <link name="wall_link">
        <visual >
            <origin xyz="0 0.4572 0" rpy="0 0 3.141592653589793" />
            <geometry >
                <mesh scale="0.001 0.001 0.001" filename="meshes/wall.stl" />
            </geometry>
            <material >
                <color rgba="0.9 0.6 0.3 1" />
            </material>
        </visual>
        <collision >
            <origin xyz="0 0.4572 0" rpy="0 0 3.141592653589793" />
            <geometry >
                <mesh scale="0.001 0.001 0.001" filename="meshes/wall.stl" />
            </geometry>
        </collision>
        <inertial >
            <origin xyz="0 0.4572 0" rpy="0 0 3.141592653589793" />
            <mass value="100" />
            <inertia iyy="1.0" iyz="0.0" ixx="1.0" ixy="0.0" izz="1.0" ixz="0.0" />
        </inertial>
    </link>
    <link name="knob_holder_1">
        <visual >
            <origin xyz="0.015 0.07962899999999999 0.3659124" rpy="0 0 -1.5707963267948966" />
            <geometry >
                <mesh scale="0.001 0.001 0.001" filename="meshes/knob_holder_1.stl" />
            </geometry>
            <material >
                <color rgba="0.7 0.7 0.7 1" />
            </material>
        </visual>
        <collision >
            <origin xyz="0.015 0.07962899999999999 0.3659124" rpy="0 0 -1.5707963267948966" />
            <geometry >
                <mesh scale="0.001 0.001 0.001" filename="meshes/knob_holder_1.stl" />
            </geometry>
            <material >
                <color rgba="0.7 0.7 0.7 1" />
            </material>
        </collision>
        <inertial >
            <origin xyz="0 0 0" rpy="0 0 0" />
            <mass value="0.2" />
            <inertia iyy="0.000833" iyz="0" ixx="0.000833" ixy="0" izz="0.000833" ixz="0" />
        </inertial>
    </link>
    <joint type="fixed" name="knob_holder_1_joint">
        <parent link="wall_link" />
        <child link="knob_holder_1" />
        <origin xyz="0 0 0" rpy="0 0 0" />
        <axis xyz="1 0 0" />
        <limit velocity="5" upper="3.141592653589793" lower="-1.5707963267948966" effort="2" />
        <dynamics friction="0.01" damping="0" />
    </joint>
    <link name="knob_1">
        <visual >
            <origin xyz="0 0 0" rpy="0 1.5707963267948966 0" />
            <geometry >
                <mesh scale="0.001 0.001 0.001" filename="meshes/knob_1.stl" />
            </geometry>
            <material >
                <color rgba="0.2 0.2 0.2 1" />
            </material>
        </visual>
        <collision >
            <origin xyz="0 0 0" rpy="0 1.5707963267948966 0" />
            <geometry >
                <mesh scale="0.001 0.001 0.001" filename="meshes/knob_1.stl" />
            </geometry>
            <material >
                <color rgba="1 1 1 1" />
            </material>
        </collision>
        <inertial >
            <origin xyz="0 0 0" rpy="0 0 0" />
            <mass value="0.4" />
            <inertia iyy="0.0001" iyz="0" ixx="0.0001" ixy="0" izz="0.0001" ixz="0" />
        </inertial>
    </link>
    <joint type="revolute" name="knob_1_joint">
        <parent link="knob_holder_1" />
        <child link="knob_1" />
        <origin xyz="0.040999999999999995 0.07962899999999999 0.3659124" rpy="0 0 0" />
        <axis xyz="1 0 0" />
        <limit velocity="5" upper="6.283185307179586" lower="0" effort="2" />
        <dynamics friction="0.01" damping="0" />
    </joint>
    <link name="knob_indicator_1">
        <visual >
            <origin xyz="0 0 0" rpy="0 1.5707963267948966 0" />
            <geometry >
                <box size="0.01 0.0025 0.001" />
            </geometry>
            <material >
                <color rgba="1 0 0 1" />
            </material>
        </visual>
    </link>
    <joint type="fixed" name="knob_indicator_1_joint_rigid">
        <parent link="knob_1" />
        <child link="knob_indicator_1" />
        <origin xyz="0.005 0 0.006" rpy="0 0 0" />
    </joint>
    <link name="knob_holder_2">
        <visual >
            <origin xyz="0.015 0.17962879999999998 0.3659124" rpy="0 0 -1.5707963267948966" />
            <geometry >
                <mesh scale="0.001 0.001 0.001" filename="meshes/knob_holder_2.stl" />
            </geometry>
            <material >
                <color rgba="0.7 0.7 0.7 1" />
            </material>
        </visual>
        <collision >
            <origin xyz="0.015 0.17962879999999998 0.3659124" rpy="0 0 -1.5707963267948966" />
            <geometry >
                <mesh scale="0.001 0.001 0.001" filename="meshes/knob_holder_2.stl" />
            </geometry>
            <material >
                <color rgba="0.7 0.7 0.7 1" />
            </material>
        </collision>
        <inertial >
            <origin xyz="0 0 0" rpy="0 0 0" />
            <mass value="0.2" />
            <inertia iyy="0.000833" iyz="0" ixx="0.000833" ixy="0" izz="0.000833" ixz="0" />
        </inertial>
    </link>
    <joint type="fixed" name="knob_holder_2_joint">
        <parent link="wall_link" />
        <child link="knob_holder_2" />
        <origin xyz="0 0 0" rpy="0 0 0" />
        <axis xyz="1 0 0" />
        <limit velocity="5" upper="3.141592653589793" lower="-1.5707963267948966" effort="2" />
        <dynamics friction="0.01" damping="0" />
    </joint>
    <link name="knob_2">
        <visual >
            <origin xyz="0 0 0" rpy="0 1.5707963267948966 0" />
            <geometry >
                <mesh scale="0.001 0.001 0.001" filename="meshes/knob_2.stl" />
            </geometry>
            <material >
                <color rgba="0.2 0.2 0.2 1" />
            </material>
        </visual>
        <collision >
            <origin xyz="0 0 0" rpy="0 1.5707963267948966 0" />
            <geometry >
                <mesh scale="0.001 0.001 0.001" filename="meshes/knob_2.stl" />
            </geometry>
            <material >
                <color rgba="1 1 1 1" />
            </material>
        </collision>
        <inertial >
            <origin xyz="0 0 0" rpy="0 0 0" />
            <mass value="0.4" />
            <inertia iyy="0.0001" iyz="0" ixx="0.0001" ixy="0" izz="0.0001" ixz="0" />
        </inertial>
    </link>
    <joint type="revolute" name="knob_2_joint">
        <parent link="knob_holder_2" />
        <child link="knob_2" />
        <origin xyz="0.027 0.17962879999999998 0.3659124" rpy="0 0 0" />
        <axis xyz="1 0 0" />
        <limit velocity="5" upper="6.283185307179586" lower="0" effort="2" />
        <dynamics friction="0.01" damping="0" />
    </joint>
    <link name="knob_indicator_2">
        <visual >
            <origin xyz="0 0 0" rpy="1.5707963267948966 3.141592653589793 1.5707963267948966" />
            <geometry >
                <box size="0.01 0.0025 0.001" />
            </geometry>
            <material >
                <color rgba="1 0 0 1" />
            </material>
        </visual>
    </link>
    <joint type="fixed" name="knob_indicator_2_joint_rigid">
        <parent link="knob_2" />
        <child link="knob_indicator_2" />
        <origin xyz="0.01 0.012 0" rpy="0 0 0" />
    </joint>
    <link name="knob_holder_3">
        <visual >
            <origin xyz="0.015 0.27962859999999995 0.3659124" rpy="0 0 -1.5707963267948966" />
            <geometry >
                <mesh scale="0.001 0.001 0.001" filename="meshes/knob_holder_3.stl" />
            </geometry>
            <material >
                <color rgba="0.7 0.7 0.7 1" />
            </material>
        </visual>
        <collision >
            <origin xyz="0.015 0.27962859999999995 0.3659124" rpy="0 0 -1.5707963267948966" />
            <geometry >
                <mesh scale="0.001 0.001 0.001" filename="meshes/knob_holder_3.stl" />
            </geometry>
            <material >
                <color rgba="0.7 0.7 0.7 1" />
            </material>
        </collision>
        <inertial >
            <origin xyz="0 0 0" rpy="0 0 0" />
            <mass value="0.2" />
            <inertia iyy="0.000833" iyz="0" ixx="0.000833" ixy="0" izz="0.000833" ixz="0" />
        </inertial>
    </link>
    <joint type="fixed" name="knob_holder_3_joint">
        <parent link="wall_link" />
        <child link="knob_holder_3" />
        <origin xyz="0 0 0" rpy="0 0 0" />
        <axis xyz="1 0 0" />
        <limit velocity="5" upper="3.141592653589793" lower="-1.5707963267948966" effort="2" />
        <dynamics friction="0.01" damping="0" />
    </joint>
    <link name="knob_3">
        <visual >
            <origin xyz="0 0 0" rpy="0 1.5707963267948966 0" />
            <geometry >
                <mesh scale="0.001 0.001 0.001" filename="meshes/knob_3.stl" />
            </geometry>
            <material >
                <color rgba="0.2 0.2 0.2 1" />
            </material>
        </visual>
        <collision >
            <origin xyz="0 0 0" rpy="0 1.5707963267948966 0" />
            <geometry >
                <mesh scale="0.001 0.001 0.001" filename="meshes/knob_3.stl" />
            </geometry>
            <material >
                <color rgba="1 1 1 1" />
            </material>
        </collision>
        <inertial >
            <origin xyz="0 0 0" rpy="0 0 0" />
            <mass value="0.4" />
            <inertia iyy="0.0001" iyz="0" ixx="0.0001" ixy="0" izz="0.0001" ixz="0" />
        </inertial>
    </link>
    <joint type="revolute" name="knob_3_joint">
        <parent link="knob_holder_3" />
        <child link="knob_3" />
        <origin xyz="0.027 0.27962859999999995 0.3659124" rpy="0 0 0" />
        <axis xyz="1 0 0" />
        <limit velocity="5" upper="6.283185307179586" lower="0" effort="2" />
        <dynamics friction="0.01" damping="0" />
    </joint>
    <link name="knob_indicator_3">
        <visual >
            <origin xyz="0 0 0" rpy="1.5707963267948966 3.141592653589793 1.5707963267948966" />
            <geometry >
                <box size="0.01 0.0025 0.001" />
            </geometry>
            <material >
                <color rgba="1 0 0 1" />
            </material>
        </visual>
    </link>
    <joint type="fixed" name="knob_indicator_3_joint_rigid">
        <parent link="knob_3" />
        <child link="knob_indicator_3" />
        <origin xyz="0.019 0.016 0" rpy="0 0 0" />
    </joint>
</robot>
